Workbook

Sheet yashu_data
A1: date | B1: 練習試合/公式戦 | C1: 対戦相手 | D1: 番号 | E1: name | F1: 打数 | G1: 安打 | H1: 塁打数 | I1: 四死球 | J1: 三振 | K1: 盗塁企図数 | L1: 盗塁成功数 | M1: 犠飛 | N1: 打点
A2: 46116 | B2: 東都春季リーグ | C2: 順天堂 | D2: 15 | E2: =_xlfn.XLOOKUP(D2,master!A:A,master!B:B) | F2: 5 | G2: 1 | H2: 1 | I2: 0 | J2: 2 | K2: 0 | L2: 0 | M2: 0 | N2: 0
A3: 46116 | B3: 東都春季リーグ | C3: 順天堂 | D3: 28 | E3: =_xlfn.XLOOKUP(D3,master!A:A,master!B:B) | F3: 3 | G3: 0 | H3: 0 | I3: 1 | J3: 2 | K3: 0 | L3: 0 | M3: 0 | N3: 0
A4: 46116 | B4: 東都春季リーグ | C4: 順天堂 | D4: 5 | E4: =_xlfn.XLOOKUP(D4,master!A:A,master!B:B) | F4: 1 | G4: 0 | H4: 0 | I4: 0 | J4: 1 | K4: 0 | L4: 0 | M4: 0 | N4: 0
A5: 46116 | B5: 東都春季リーグ | C5: 順天堂 | D5: 30 | E5: =_xlfn.XLOOKUP(D5,master!A:A,master!B:B) | F5: 4 | G5: 2 | H5: 3 | I5: 0 | J5: 0 | K5: 0 | L5: 0 | M5: 0 | N5: 0
A6: 46116 | B6: 東都春季リーグ | C6: 順天堂 | D6: 27 | E6: =_xlfn.XLOOKUP(D6,master!A:A,master!B:B) | F6: 4 | G6: 0 | H6: 0 | I6: 0 | J6: 0 | K6: 0 | L6: 0 | M6: 0 | N6: 0
A7: 46116 | B7: 東都春季リーグ | C7: 順天堂 | D7: 2 | E7: =_xlfn.XLOOKUP(D7,master!A:A,master!B:B) | F7: 3 | G7: 1 | H7: 1 | I7: 0 | J7: 1 | K7: 0 | L7: 0 | M7: 0 | N7: 1
A8: 46116 | B8: 東都春季リーグ | C8: 順天堂 | D8: 12 | E8: =_xlfn.XLOOKUP(D8,master!A:A,master!B:B) | F8: 4 | G8: 3 | H8: 3 | I8: 0 | J8: 0 | K8: 1 | L8: 1 | M8: 0 | N8: 0
A9: 46116 | B9: 東都春季リーグ | C9: 順天堂 | D9: 3 | E9: =_xlfn.XLOOKUP(D9,master!A:A,master!B:B) | F9: 4 | G9: 1 | H9: 1 | I9: 0 | J9: 0 | K9: 0 | L9: 0 | M9: 0 | N9: 1
A10: 46116 | B10: 東都春季リーグ | C10: 順天堂 | D10: 19 | E10: =_xlfn.XLOOKUP(D10,master!A:A,master!B:B) | F10: 3 | G10: 0 | H10: 0 | I10: 0 | J10: 2 | K10: 0 | L10: 0 | M10: 0 | N10: 0
A11: 46116 | B11: 東都春季リーグ | C11: 順天堂 | D11: 26 | E11: 鈴木瑛心 | F11: 1 | G11: 0 | H11: 0 | I11: 0 | J11: 1 | K11: 0 | L11: 0 | M11: 0 | N11: 0
A12: 46116 | B12: 東都春季リーグ | C12: 順天堂 | D12: 7 | E12: =_xlfn.XLOOKUP(D12,master!A:A,master!B:B) | F12: 3 | G12: 1 | H12: 2 | I12: 1 | J12: 0 | K12: 0 | L12: 0 | M12: 0 | N12: 0
A13: 46117 | B13: 東都春季リーグ | C13: 順天堂 | D13: 12 | E13: =_xlfn.XLOOKUP(D13,master!A:A,master!B:B) | F13: 3 | G13: 2 | H13: 2 | I13: 3 | J13: 0 | K13: 2 | L13: 1 | M13: 0 | N13: 2
A14: 46117 | B14: 東都春季リーグ | C14: 順天堂 | D14: 28 | E14: =_xlfn.XLOOKUP(D14,master!A:A,master!B:B) | F14: 3 | G14: 1 | H14: 1 | I14: 0 | J14: 0 | K14: 0 | L14: 0 | M14: 3 | N14: 1
A15: 46117 | B15: 東都春季リーグ | C15: 順天堂 | D15: 30 | E15: =_xlfn.XLOOKUP(D15,master!A:A,master!B:B) | F15: 5 | G15: 3 | H15: 4 | I15: 1 | J15: 0 | K15: 0 | L15: 0 | M15: 0 | N15: 1
A16: 46117 | B16: 東都春季リーグ | C16: 順天堂 | D16: 27 | E16: =_xlfn.XLOOKUP(D16,master!A:A,master!B:B) | F16: 3 | G16: 2 | H16: 2 | I16: 2 | J16: 0 | K16: 1 | L16: 1 | M16: 0 | N16: 1
A17: 46117 | B17: 東都春季リーグ | C17: 順天堂 | D17: 8 | E17: =_xlfn.XLOOKUP(D17,master!A:A,master!B:B) | F17: 1 | G17: 0 | H17: 0 | I17: 0 | J17: 0 | K17: 1 | L17: 1 | M17: 0 | N17: 0
A18: 46117 | B18: 東都春季リーグ | C18: 順天堂 | D18: 2 | E18: =_xlfn.XLOOKUP(D18,master!A:A,master!B:B) | F18: 6 | G18: 3 | H18: 5 | I18: 0 | J18: 0 | K18: 0 | L18: 0 | M18: 0 | N18: 3
A19: 46117 | B19: 東都春季リーグ | C19: 順天堂 | D19: 15 | E19: =_xlfn.XLOOKUP(D19,master!A:A,master!B:B) | F19: 5 | G19: 4 | H19: 7 | I19: 0 | J19: 1 | K19: 0 | L19: 0 | M19: 0 | N19: 5
A20: 46117 | B20: 東都春季リーグ | C20: 順天堂 | D20: 5 | E20: =_xlfn.XLOOKUP(D20,master!A:A,master!B:B) | F20: 1 | G20: 0 | H20: 0 | I20: 0 | J20: 1 | K20: 0 | L20: 0 | M20: 0 | N20: 0
A21: 46117 | B21: 東都春季リーグ | C21: 順天堂 | D21: 16 | E21: =_xlfn.XLOOKUP(D21,master!A:A,master!B:B) | F21: 0 | G21: 0 | H21: 0 | I21: 0 | J21: 0 | K21: 0 | L21: 0 | M21: 0 | N21: 0
A22: 46117 | B22: 東都春季リーグ | C22: 順天堂 | D22: 3 | E22: =_xlfn.XLOOKUP(D22,master!A:A,master!B:B) | F22: 3 | G22: 0 | H22: 0 | I22: 0 | J22: 1 | K22: 0 | L22: 0 | M22: 0 | N22: 0
A23: 46117 | B23: 東都春季リーグ | C23: 順天堂 | D23: 22 | E23: =_xlfn.XLOOKUP(D23,master!A:A,master!B:B) | F23: 1 | G23: 0 | H23: 0 | I23: 0 | J23: 0 | K23: 0 | L23: 0 | M23: 1 | N23: 0
... A44: 46124 | B44: 東都春季リーグ | C44: 科学大 | D44: 15 | E44: =_xlfn.XLOOKUP(D44,master!A:A,master!B:B) | F44: 5 | G44: 3 | H44: 4 | I44: 0 | J44: 0 | K44: 0 | L44: 0 | M44: 0 | N44: 1
A45: 46125 | B45: 東都春季リーグ | C45: 科学大 | D45: 9 | E45: 藤永陸言 | F45: 0 | G45: 0 | H45: 0 | I45: 0 | J45: 0 | K45: 0 | L45: 0 | M45: 1 | N45: 0
A46: 46124 | B46: 東都春季リーグ | C46: 科学大 | D46: 3 | E46: =_xlfn.XLOOKUP(D46,master!A:A,master!B:B) | F46: 4 | G46: 2 | H46: 2 | I46: 0 | J46: 0 | K46: 1 | L46: 1 | M46: 0 | N46: 1
A47: 46124 | B47: 東都春季リーグ | C47: 科学大 | D47: 26 | E47: =_xlfn.XLOOKUP(D47,master!A:A,master!B:B) | F47: 2 | G47: 0 | H47: 0 | I47: 0 | J47: 2 | K47: 0 | L47: 0 | M47: 0 | N47: 0
A48: 46124 | B48: 東都春季リーグ | C48: 科学大 | D48: 24 | E48: =_xlfn.XLOOKUP(D48,master!A:A,master!B:B) | F48: 1 | G48: 0 | H48: 0 | I48: 0 | J48: 1 | K48: 0 | L48: 0 | M48: 0 | N48: 0
A49: 46124 | B49: 東都春季リーグ | C49: 科学大 | D49: 22 | E49: =_xlfn.XLOOKUP(D49,master!A:A,master!B:B) | F49: 1 | G49: 0 | H49: 0 | I49: 0 | J49: 1 | K49: 0 | L49: 0 | M49: 1 | N49: 1
A50: 46124 | B50: 東都春季リーグ | C50: 科学大 | D50: 7 | E50: =_xlfn.XLOOKUP(D50,master!A:A,master!B:B) | F50: 5 | G50: 2 | H50: 2 | I50: 0 | J50: 0 | K50: 0 | L50: 0 | M50: 0 | N50: 2
A51: 46130 | B51: 東都春季リーグ | C51: 都市大学 | D51: 12 | E51: =_xlfn.XLOOKUP(D51,master!A:A,master!B:B) | F51: 5 | G51: 0 | H51: 0 | I51: 0 | J51: 1 | K51: 0 | L51: 0 | M51: 0 | N51: 0
A52: 46130 | B52: 東都春季リーグ | C52: 都市大学 | D52: 28 | E52: =_xlfn.XLOOKUP(D52,master!A:A,master!B:B) | F52: 4 | G52: 1 | H52: 1 | I52: 0 | J52: 0 | K52: 0 | L52: 0 | M52: 1 | N52: 0
A53: 46130 | B53: 東都春季リーグ | C53: 都市大学 | D53: 30 | E53: =_xlfn.XLOOKUP(D53,master!A:A,master!B:B) | F53: 5 | G53: 1 | H53: 2 | I53: 0 | J53: 0 | K53: 0 | L53: 0 | M53: 0 | N53: 1
A54: 46130 | B54: 東都春季リーグ | C54: 都市大学 | D54: 27 | E54: =_xlfn.XLOOKUP(D54,master!A:A,master!B:B) | F54: 5 | G54: 2 | H54: 2 | I54: 0 | J54: 0 | K54: 0 | L54: 0 | M54: 0 | N54: 1
A55: 46130 | B55: 東都春季リーグ | C55: 都市大学 | D55: 2 | E55: =_xlfn.XLOOKUP(D55,master!A:A,master!B:B) | F55: 5 | G55: 3 | H55: 4 | I55: 0 | J55: 0 | K55: 0 | L55: 0 | M55: 0 | N55: 2
A56: 46130 | B56: 東都春季リーグ | C56: 都市大学 | D56: 15 | E56: =_xlfn.XLOOKUP(D56,master!A:A,master!B:B) | F56: 5 | G56: 3 | H56: 4 | I56: 0 | J56: 0 | K56: 0 | L56: 0 | M56: 0 | N56: 1
A57: 46130 | B57: 東都春季リーグ | C57: 都市大学 | D57: 3 | E57: =_xlfn.XLOOKUP(D57,master!A:A,master!B:B) | F57: 4 | G57: 0 | H57: 0 | I57: 1 | J57: 0 | K57: 0 | L57: 0 | M57: 0 | N57: 1
... A73: 46131 | B73: 東都春季リーグ | C73: 都市大学 | D73: 7 | E73: =_xlfn.XLOOKUP(D73,master!A:A,master!B:B) | F73: 1 | G73: 0 | H73: 0 | I73: 1 | J73: 0 | K73: 0 | L73: 0 | M73: 0 | N73: 0
A74: 46137 | B74: 東都春季リーグ | C74: 順天堂大学 | D74: 12 | E74: 平野顕太郎 | F74: 4 | G74: 1 | H74: 1 | I74: 0 | J74: 1 | K74: 0 | L74: 0 | M74: 0 | N74: 1
A75: 46137 | B75: 東都春季リーグ | C75: 順天堂大学 | D75: 22 | E75: 椎名龍 | F75: 2 | G75: 2 | H75: 2 | I75: 0 | J75: 0 | K75: 1 | L75: 0 | M75: 1 | N75: 0
...

Sheet master
A1: 番号 | B1: name
A2: 1 | B2: 松浦有汰
A3: 17 | B3: 大津遼弥
A4: 14 | B4: 高田怜旺
A5: 15 | B5: 上村瑛
A6: 18 | B6: 鳥山雅史
A7: 11 | B7: 深谷神牙
A8: 21 | B8: 安崎隼翔
A9: 29 | B9: 香川颯輝
A10: 10 | B10: 木部太陽
A11: 2 | B11: 川田朝風
A12: 19 | B12: 岩村健太
A13: 12 | B13: 平野顕太郎
... A31: 38 | B31: 栗原歩夢

Sheet toushu_data

Sheet 統計
A1: ■ 通算（全試合合計） 成績
A2: 番号 | B2: name | C2: 打数 | D2: 安打 | E2: 塁打数 | F2: 四死球 | G2: 三振 | H2: 企図 | I2: 成功 | J2: 犠飛 | K2: 打点 | L2: 打率 | M2: 長打率 | N2: 出塁率 | O2: OPS | P2: Rank | Q2: 番号(再) | R2: name(再) | U2: 番号 | V2: name | W2: 投球回 | X2: 被安打 | Y2: 与四死球 | Z2: 奪三振 | AA2: 自責点 | AB2: 防御率 | AC2: 被打率 | AD2: 与球率 | AE2: 奪三振率 | AF2: WHIP | AG2: 番号(再) | AH2: name(再)
A3: 1 | B3: 松浦有汰 | C3: 27 | D3: 5 | E3: 7 | F3: 8 | G3: 1 | H3: 0 | I3: 0 | J3: 2 | K3: 3 | L3: 0.18518519 | M3: 0.25925926 | N3: 0.35135135 | O3: 0.61061061 | P3: Rank: C | Q3: 1 | R3: 松浦有汰
A4: 2 | B4: 川田朝風 | C4: 49 | D4: 15 | E4: 22 | F4: 3 | G4: 4 | H4: 1 | I4: 1 | J4: 3 | K4: 12 | L4: 0.30612245 | M4: 0.44897959 | N4: 0.32727273 | O4: 0.77625232 | P4: Rank: B | Q4: 2 | R4: 川田朝風
A5: 3 | B5: 佐野憲紳 | C5: 43 | D5: 14 | E5: 19 | F5: 3 | G5: 5 | H5: 2 | I5: 1 | J5: 1 | K5: 8 | L5: 0.3255814 | M5: 0.44186047 | N5: 0.36170213 | O5: 0.80356259 | P5: Rank: B | Q5: 3 | R5: 佐野憲紳
A6: 4 | B6: 土屋晧介 | C6: 3 | D6: 2 | E6: 2 | F6: 2 | G6: 0 | H6: 0 | I6: 0 | J6: 0 | K6: 1 | L6: 0.66666667 | M6: 0.66666667 | N6: 0.8 | O6: 1.4666667 | Q6: 4 | R6: 土屋晧介
A7: 5 | B7: 田中堅 | C7: 3 | D7: 0 | E7: 0 | F7: 0 | G7: 2 | H7: 0 | I7: 0 | J7: 0 | K7: 0 | L7: 0 | M7: 0 | N7: 0 | O7: 0 | Q7: 5 | R7: 田中堅
A8: 6 | B8: 國分涼 | C8: 0 | D8: 0 | E8: 0 | F8: 0 | G8: 0 | H8: 0 | I8: 0 | J8: 0 | K8: 0 | L8: 0 | M8: 0 | N8: 0 | O8: 0 | Q8: 6 | R8: 國分涼
A9: 7 | B9: 金田将弥 | C9: 29 | D9: 7 | E9: 11 | F9: 5 | G9: 1 | H9: 0 | I9: 0 | J9: 0 | K9: 4 | L9: 0.24137931 | M9: 0.37931034 | N9: 0.35294118 | O9: 0.73225152 | P9: Rank: B | Q9: 7 | R9: 金田将弥
A10: 8 | B10: 樋口結 | C10: 6 | D10: 1 | E10: 2 | F10: 0 | G10: 2 | H10: 1 | I10: 1 | J10: 0 | K10: 1 | L10: 0.16666667 | M10: 0.33333333 | N10: 0.16666667 | O10: 0.5 | P10: Rank: C | Q10: 8 | R10: 樋口結
A11: 9 | B11: 藤永陸言 | C11: 13 | D11: 2 | E11: 3 | F11: 0 | G11: 2 | H11: 1 | I11: 1 | J11: 1 | K11: 2 | L11: 0.15384615 | M11: 0.23076923 | N11: 0.14285714 | O11: 0.37362637 | P11: Rank: C | Q11: 9 | R11: 藤永陸言
A12: 12 | B12: 平野顕太郎 | C12: 47 | D12: 13 | E12: 14 | F12: 6 | G12: 8 | H12: 6 | I12: 4 | J12: 0 | K12: 6 | L12: 0.27659574 | M12: 0.29787234 | N12: 0.35849057 | O12: 0.65636291 | P12: Rank: C | Q12: 12 | R12: 平野顕太郎
A13: 13 | B13: 福嶋聖知 | C13: 1 | D13: 1 | E13: 1 | F13: 0 | G13: 0 | H13: 0 | I13: 0 | J13: 0 | K13: 0 | L13: 1 | M13: 1 | N13: 1 | O13: 2 | Q13: 13 | R13: 福嶋聖知
A14: 15 | B14: 上村瑛 | C14: 56 | D14: 25 | E14: 35 | F14: 3 | G14: 3 | H14: 2 | I14: 2 | J14: 0 | K14: 11 | L14: 0.44642857 | M14: 0.625 | N14: 0.47457627 | O14: 1.0995763 | P14: Rank: S | Q14: 15 | R14: 上村瑛
A15: 16 | B15: 齋藤遼芽 | C15: 1 | D15: 0 | E15: 0 | F15: 0 | G15: 0 | H15: 0 | I15: 0 | J15: 0 | K15: 0 | L15: 0 | M15: 0 | N15: 0 | O15: 0 | Q15: 16 | R15: 齋藤遼芽
A16: 19 | B16: 岩村健太 | C16: 31 | D16: 11 | E16: 12 | F16: 3 | G16: 5 | H16: 1 | I16: 1 | J16: 4 | K16: 3 | L16: 0.35483871 | M16: 0.38709677 | N16: 0.36842105 | O16: 0.75551783 | P16: Rank: B | Q16: 19 | R16: 岩村健太
A17: 22 | B17: 椎名龍 | C17: 21 | D17: 6 | E17: 7 | F17: 2 | G17: 3 | H17: 2 | I17: 1 | J17: 3 | K17: 1 | L17: 0.28571429 | M17: 0.33333333 | N17: 0.30769231 | O17: 0.64102564 | P17: Rank: C | Q17: 22 | R17: 椎名龍
A18: 24 | B18: 磯村亮太 | C18: 12 | D18: 2 | E18: 2 | F18: 2 | G18: 2 | H18: 0 | I18: 0 | J18: 0 | K18: 0 | L18: 0.16666667 | M18: 0.16666667 | N18: 0.28571429 | O18: 0.45238095 | P18: Rank: C | Q18: 24 | R18: 磯村亮太
A19: 26 | B19: 鈴木瑛心 | C19: 9 | D19: 0 | E19: 0 | F19: 0 | G19: 3 | H19: 0 | I19: 0 | J19: 0 | K19: 0 | L19: 0 | M19: 0 | N19: 0 | O19: 0 | P19: Rank: C | Q19: 26 | R19: 鈴木瑛心
A20: 27 | B20: 木暮啓人 | C20: 45 | D20: 11 | E20: 20 | F20: 9 | G20: 7 | H20: 3 | I20: 3 | J20: 0 | K20: 6 | L20: 0.24444444 | M20: 0.44444444 | N20: 0.37037037 | O20: 0.81481481 | P20: Rank: B | Q20: 27 | R20: 木暮啓人
A21: 28 | B21: 霜越心聡 | C21: 21 | D21: 5 | E21: 5 | F21: 2 | G21: 5 | H21: 0 | I21: 0 | J21: 6 | K21: 2 | L21: 0.23809524 | M21: 0.23809524 | N21: 0.24137931 | O21: 0.47947455 | P21: Rank: C | Q21: 28 | R21: 霜越心聡
A22: 30 | B22: 本山啓治 | C22: 51 | D22: 20 | E22: 30 | F22: 3 | G22: 4 | H22: 0 | I22: 0 | J22: 1 | K22: 10 | L22: 0.39215686 | M22: 0.58823529 | N22: 0.41818182 | O22: 1.0064171 | P22: Rank: S | Q22: 30 | R22: 本山啓治
A23: 32 | B23: 石川昊翔 | C23: 0 | D23: 0 | E23: 0 | F23: 0 | G23: 0 | H23: 0 | I23: 0 | J23: 0 | K23: 0 | L23: 0 | M23: 0 | N23: 0 | O23: 0 | Q23: 32 | R23: 石川昊翔
A24: 33 | B24: 不明 | C24: 1 | D24: 0 | E24: 0 | F24: 0 | G24: 0 | H24: 0 | I24: 0 | J24: 0 | K24: 0 | L24: 0 | M24: 0 | N24: 0 | O24: 0 | Q24: 33 | R24: 不明
A25: 38 | B25: 栗原歩夢 | C25: 0 | D25: 0 | E25: 0 | F25: 0 | G25: 0 | H25: 0 | I25: 0 | J25: 0 | K25: 0 | L25: 0 | M25: 0 | N25: 0 | O25: 0 | Q25: 38 | R25: 栗原歩夢
A27: ■ 2026-04 成績
A28: 番号 | B28: name | C28: 打数 | D28: 安打 | E28: 塁打数 | F28: 四死球 | G28: 三振 | H28: 企図 | I28: 成功 | J28: 犠飛 | K28: 打点 | L28: 打率 | M28: 長打率 | N28: 出塁率 | O28: OPS | P28: Rank | Q28: 番号(再) | R28: name(再) | U28: 番号 | V28: name | W28: 投球回 | X28: 被安打 | Y28: 与四死球 | Z28: 奪三振 | AA28: 自責点 | AB28: 防御率 | AC28: 被打率 | AD28: 与球率 | AE28: 奪三振率 | AF28: WHIP | AG28: 番号(再) | AH28: name(再)
A29: 1 | B29: 松浦有汰 | C29: 6 | D29: 1 | E29: 1 | F29: 1 | G29: 0 | H29: 0 | I29: 0 | J29: 1 | K29: 0 | L29: 0.16666667 | M29: 0.16666667 | N29: 0.25 | O29: 0.41666667 | P29: Rank: C | Q29: 1 | R29: 松浦有汰
A30: 2 | B30: 川田朝風 | C30: 28 | D30: 9 | E30: 12 | F30: 2 | G30: 2 | H30: 1 | I30: 1 | J30: 1 | K30: 6 | L30: 0.32142857 | M30: 0.42857143 | N30: 0.35483871 | O30: 0.78341014 | P30: Rank: B | Q30: 2 | R30: 川田朝風
A31: 3 | B31: 佐野憲紳 | C31: 24 | D31: 6 | E31: 6 | F31: 2 | G31: 2 | H31: 1 | I31: 1 | J31: 0 | K31: 3 | L31: 0.25 | M31: 0.25 | N31: 0.30769231 | O31: 0.55769231 | P31: Rank: C | Q31: 3 | R31: 佐野憲紳
A32: 5 | B32: 田中堅 | C32: 3 | D32: 0 | E32: 0 | F32: 0 | G32: 2 | H32: 0 | I32: 0 | J32: 0 | K32: 0 | L32: 0 | M32: 0 | N32: 0 | O32: 0 | Q32: 5 | R32: 田中堅
A33: 7 | B33: 金田将弥 | C33: 18 | D33: 3 | E33: 4 | F33: 3 | G33: 0 | H33: 0 | I33: 0 | J33: 0 | K33: 2 | L33: 0.16666667 | M33: 0.22222222 | N33: 0.28571429 | O33: 0.50793651 | P33: Rank: C | Q33: 7 | R33: 金田将弥
A34: 8 | B34: 樋口結 | C34: 1 | D34: 0 | E34: 0 | F34: 0 | G34: 0 | H34: 1 | I34: 1 | J34: 0 | K34: 0 | L34: 0 | M34: 0 | N34: 0 | O34: 0 | Q34: 8 | R34: 樋口結
A35: 9 | B35: 藤永陸言 | C35: 7 | D35: 1 | E35: 1 | F35: 0 | G35: 1 | H35: 0 | I35: 0 | J35: 1 | K35: 0 | L35: 0.14285714 | M35: 0.14285714 | N35: 0.125 | O35: 0.26785714 | P35: Rank: C | Q35: 9 | R35: 藤永陸言
A36: 12 | B36: 平野顕太郎 | C36: 29 | D36: 10 | E36: 10 | F36: 6 | G36: 6 | H36: 5 | I36: 3 | J36: 0 | K36: 3 | L36: 0.34482759 | M36: 0.34482759 | N36: 0.45714286 | O36: 0.80197044 | P36: Rank: B | Q36: 12 | R36: 平野顕太郎
A37: 13 | B37: 福嶋聖知 | C37: 1 | D37: 1 | E37: 1 | F37: 0 | G37: 0 | H37: 0 | I37: 0 | J37: 0 | K37: 0 | L37: 1 | M37: 1 | N37: 1 | O37: 2 | Q37: 13 | R37: 福嶋聖知
A38: 15 | B38: 上村瑛 | C38: 31 | D38: 14 | E38: 21 | F38: 1 | G38: 3 | H38: 0 | I38: 0 | J38: 0 | K38: 9 | L38: 0.4516129 | M38: 0.67741935 | N38: 0.46875 | O38: 1.1461694 | P38: Rank: S | Q38: 15 | R38: 上村瑛
A39: 16 | B39: 齋藤遼芽 | C39: 1 | D39: 0 | E39: 0 | F39: 0 | G39: 0 | H39: 0 | I39: 0 | J39: 0 | K39: 0 | L39: 0 | M39: 0 | N39: 0 | O39: 0 | Q39: 16 | R39: 齋藤遼芽
A40: 19 | B40: 岩村健太 | C40: 11 | D40: 3 | E40: 4 | F40: 0 | G40: 2 | H40: 0 | I40: 0 | J40: 0 | K40: 1 | L40: 0.27272727 | M40: 0.36363636 | N40: 0.27272727 | O40: 0.63636364 | P40: Rank: C | Q40: 19 | R40: 岩村健太
A41: 22 | B41: 椎名龍 | C41: 6 | D41: 3 | E41: 4 | F41: 0 | G41: 1 | H41: 1 | I41: 0 | J41: 3 | K41: 1 | L41: 0.5 | M41: 0.66666667 | N41: 0.33333333 | O41: 1 | P41: Rank: S | Q41: 22 | R41: 椎名龍
...
